ply
format ascii 1.0
comment : MagicaVoxel @ Ephtracy
element vertex 164
property float x
property float y
property float z
property uchar red
property uchar green
property uchar blue
end_header
0 0 -1 102 51 0
0 0 0 102 51 0
-1 -3 1 125 150 49
0 -3 1 127 141 55
-1 -2 1 127 141 55
0 -2 1 125 150 49
1 -2 1 125 150 49
-2 -1 1 127 141 55
-1 -1 1 127 141 55
0 -1 1 125 150 49
1 -1 1 125 150 49
2 -1 1 125 150 49
3 -1 1 125 150 49
-3 0 1 125 150 49
-2 0 1 125 150 49
-1 0 1 125 150 49
0 0 1 126 145 52
1 0 1 125 150 49
2 0 1 125 150 49
3 0 1 125 150 49
-2 1 1 125 150 49
-1 1 1 125 150 49
0 1 1 125 150 49
1 1 1 125 150 49
2 1 1 125 150 49
-1 2 1 125 150 49
0 2 1 125 150 49
1 2 1 125 150 49
0 3 1 125 150 49
0 -2 2 127 141 55
0 -1 2 127 141 55
-1 0 2 127 141 55
0 0 2 126 145 52
1 0 2 125 150 49
2 0 2 125 150 49
0 1 2 125 150 49
0 2 2 125 150 49
0 -3 3 125 150 49
-1 -2 3 125 150 49
0 -2 3 125 150 49
1 -2 3 125 150 49
-2 -1 3 125 150 49
-1 -1 3 125 150 49
0 -1 3 125 150 49
1 -1 3 125 150 49
2 -1 3 125 150 49
-3 0 3 125 150 49
-2 0 3 125 150 49
-1 0 3 125 150 49
0 0 3 126 145 52
1 0 3 125 150 49
2 0 3 125 150 49
-2 1 3 125 150 49
-1 1 3 125 150 49
0 1 3 125 150 49
1 1 3 125 150 49
2 1 3 125 150 49
-1 2 3 125 150 49
0 2 3 125 150 49
-1 3 3 125 150 49
0 -2 4 125 150 49
0 -1 4 125 150 49
-2 0 4 127 141 55
-1 0 4 125 150 49
0 0 4 126 145 52
1 0 4 127 141 55
2 0 4 127 141 55
0 1 4 125 150 49
0 2 4 125 150 49
-1 -2 5 127 141 55
0 -2 5 127 141 55
1 -2 5 127 141 55
-1 -1 5 127 141 55
0 -1 5 125 150 49
1 -1 5 127 141 55
2 -1 5 127 141 55
-2 0 5 127 141 55
-1 0 5 125 150 49
0 0 5 126 145 52
1 0 5 125 150 49
2 0 5 127 141 55
-2 1 5 125 150 49
-1 1 5 125 150 49
0 1 5 125 150 49
1 1 5 125 150 49
2 1 5 125 150 49
-1 2 5 125 150 49
0 2 5 125 150 49
1 2 5 125 150 49
-1 0 6 127 141 55
0 0 6 102 51 0
1 0 6 127 141 55
0 1 6 125 150 49
-1 -2 7 127 141 55
0 -2 7 127 141 55
1 -2 7 127 141 55
-1 -1 7 125 150 49
0 -1 7 127 141 55
1 -1 7 127 141 55
2 -1 7 127 141 55
-2 0 7 125 150 49
-1 0 7 125 150 49
0 0 7 126 145 52
1 0 7 125 150 49
2 0 7 127 141 55
-1 1 7 125 150 49
0 1 7 125 150 49
1 1 7 125 150 49
2 1 7 127 141 55
0 2 7 125 150 49
1 2 7 127 141 55
0 -1 8 127 141 55
-1 0 8 125 150 49
0 0 8 126 145 52
1 0 8 127 141 55
0 1 8 127 141 55
0 -2 9 127 141 55
-1 -1 9 125 150 49
0 -1 9 125 150 49
1 -1 9 127 141 55
-2 0 9 125 150 49
-1 0 9 125 150 49
0 0 9 126 145 52
1 0 9 125 150 49
2 0 9 125 150 49
-1 1 9 125 150 49
0 1 9 125 150 49
1 1 9 125 150 49
0 2 9 127 141 55
0 -1 10 127 141 55
-1 0 10 125 150 49
0 0 10 126 145 52
1 0 10 125 150 49
0 1 10 127 141 55
-1 -1 11 127 141 55
0 -1 11 127 141 55
1 -1 11 125 150 49
-1 0 11 125 150 49
0 0 11 126 145 52
1 0 11 125 150 49
-1 1 11 127 141 55
0 1 11 125 150 49
1 1 11 125 150 49
0 -1 12 127 141 55
-1 0 12 125 150 49
0 0 12 126 145 52
1 0 12 125 150 49
0 1 12 127 141 55
-1 -1 13 127 141 55
0 -1 13 125 150 49
1 -1 13 125 150 49
-1 0 13 125 150 49
0 0 13 126 145 52
1 0 13 125 150 49
-1 1 13 127 141 55
0 1 13 125 150 49
0 -1 14 127 141 55
-1 0 14 127 141 55
0 0 14 126 145 52
1 0 14 125 150 49
0 1 14 125 150 49
0 0 15 125 150 49
0 0 16 125 150 49
0 0 17 125 150 49
