ply
format ascii 1.0
comment : MagicaVoxel @ Ephtracy
element vertex 85
property float x
property float y
property float z
property uchar red
property uchar green
property uchar blue
end_header
0 0 0 221 221 221
0 0 1 238 238 238
0 0 2 238 238 238
0 0 3 221 221 221
1 0 3 141 180 105
0 0 4 238 238 238
0 0 5 238 238 238
1 0 5 141 180 105
0 1 5 141 180 105
1 1 5 141 180 105
0 -1 6 141 180 105
-1 0 6 141 180 105
0 0 6 238 238 238
1 0 6 141 180 105
0 1 6 141 180 105
1 1 6 141 180 105
1 2 6 141 180 105
0 -2 7 141 180 105
-1 -1 7 137 160 65
0 -1 7 141 180 105
1 -1 7 142 187 119
-1 0 7 137 160 65
0 0 7 238 238 238
1 0 7 141 180 105
2 0 7 142 187 119
0 1 7 142 187 119
1 1 7 141 180 105
1 2 7 141 180 105
-1 -2 8 137 160 65
0 -2 8 142 187 119
-1 -1 8 137 160 65
0 -1 8 141 180 105
1 -1 8 141 180 105
2 -1 8 141 180 105
-2 0 8 141 180 105
-1 0 8 141 180 105
0 0 8 238 238 238
1 0 8 141 180 105
2 0 8 142 187 119
-1 1 8 142 187 119
0 1 8 141 180 105
1 1 8 137 160 65
0 2 8 141 180 105
1 2 8 137 160 65
0 -2 9 137 160 65
-1 -1 9 142 187 119
0 -1 9 141 180 105
1 -1 9 141 180 105
-2 0 9 141 180 105
-1 0 9 141 180 105
0 0 9 238 238 238
1 0 9 141 180 105
2 0 9 142 187 119
-2 1 9 142 187 119
-1 1 9 141 180 105
0 1 9 141 180 105
1 1 9 137 160 65
0 2 9 141 180 105
0 -2 10 137 160 65
-2 -1 10 143 194 133
-1 -1 10 142 187 119
0 -1 10 141 180 105
1 -1 10 141 180 105
-2 0 10 141 180 105
-1 0 10 141 180 105
0 0 10 238 238 238
1 0 10 141 180 105
2 0 10 137 160 65
-1 1 10 142 187 119
0 1 10 141 180 105
1 1 10 137 160 65
0 2 10 141 180 105
-1 -1 11 143 194 133
0 -1 11 142 187 119
-1 0 11 143 194 133
0 0 11 238 238 238
1 0 11 137 160 65
0 1 11 141 180 105
0 -1 12 141 180 105
-1 0 12 143 194 133
0 0 12 238 238 238
1 0 12 141 180 105
0 1 12 142 187 119
0 0 13 143 194 133
0 0 14 143 194 133
