ply
format ascii 1.0
comment : MagicaVoxel @ Ephtracy
element vertex 85
property float x
property float y
property float z
property uchar red
property uchar green
property uchar blue
end_header
0 0 0 221 221 221
0 0 1 221 221 221
0 0 2 221 221 221
0 0 3 221 221 221
1 0 3 141 180 105
0 0 4 221 221 221
0 0 5 221 221 221
1 0 5 141 180 105
0 1 5 141 180 105
1 1 5 141 180 105
0 -1 6 141 180 105
-1 0 6 141 180 105
0 0 6 221 221 221
1 0 6 141 180 105
0 1 6 141 180 105
1 1 6 141 180 105
1 2 6 141 180 105
0 -2 7 141 180 105
-1 -1 7 141 180 105
0 -1 7 141 180 105
1 -1 7 141 180 105
-1 0 7 141 180 105
0 0 7 221 221 221
1 0 7 141 180 105
2 0 7 141 180 105
0 1 7 141 180 105
1 1 7 141 180 105
1 2 7 141 180 105
-1 -2 8 141 180 105
0 -2 8 141 180 105
-1 -1 8 141 180 105
0 -1 8 141 180 105
1 -1 8 141 180 105
2 -1 8 141 180 105
-2 0 8 141 180 105
-1 0 8 141 180 105
0 0 8 221 221 221
1 0 8 141 180 105
2 0 8 141 180 105
-1 1 8 141 180 105
0 1 8 141 180 105
1 1 8 141 180 105
0 2 8 141 180 105
1 2 8 141 180 105
0 -2 9 141 180 105
-1 -1 9 141 180 105
0 -1 9 141 180 105
1 -1 9 141 180 105
-2 0 9 141 180 105
-1 0 9 141 180 105
0 0 9 221 221 221
1 0 9 141 180 105
2 0 9 141 180 105
-2 1 9 141 180 105
-1 1 9 141 180 105
0 1 9 141 180 105
1 1 9 141 180 105
0 2 9 141 180 105
0 -2 10 141 180 105
-2 -1 10 141 180 105
-1 -1 10 141 180 105
0 -1 10 141 180 105
1 -1 10 141 180 105
-2 0 10 141 180 105
-1 0 10 141 180 105
0 0 10 221 221 221
1 0 10 141 180 105
2 0 10 141 180 105
-1 1 10 141 180 105
0 1 10 141 180 105
1 1 10 141 180 105
0 2 10 141 180 105
-1 -1 11 141 180 105
0 -1 11 141 180 105
-1 0 11 141 180 105
0 0 11 221 221 221
1 0 11 141 180 105
0 1 11 141 180 105
0 -1 12 141 180 105
-1 0 12 141 180 105
0 0 12 221 221 221
1 0 12 141 180 105
0 1 12 141 180 105
0 0 13 141 180 105
0 0 14 141 180 105
