ply
format ascii 1.0
comment : MagicaVoxel @ Ephtracy
element vertex 324
property float x
property float y
property float z
property uchar red
property uchar green
property uchar blue
end_header
1 -1 -4 136 136 136
2 -1 -4 136 136 136
2 -5 -3 136 136 136
3 -5 -3 136 136 136
4 -5 -3 136 136 136
2 -4 -3 136 136 136
3 -4 -3 136 136 136
4 -4 -3 136 136 136
1 -3 -3 136 136 136
2 -3 -3 136 136 136
1 -2 -3 136 136 136
2 -2 -3 136 136 136
3 -2 -3 136 136 136
-1 -1 -3 136 136 136
0 -1 -3 136 136 136
1 -1 -3 136 136 136
2 -1 -3 136 136 136
3 -1 -3 136 136 136
-2 0 -3 136 136 136
-1 0 -3 136 136 136
0 0 -3 136 136 136
1 0 -3 136 136 136
-2 1 -3 136 136 136
-1 1 -3 136 136 136
0 1 -3 136 136 136
1 1 -3 136 136 136
2 -6 -2 119 119 119
4 -6 -2 119 119 119
1 -5 -2 119 119 119
2 -5 -2 136 136 136
3 -5 -2 136 136 136
4 -5 -2 136 136 136
5 -5 -2 136 136 136
0 -4 -2 136 136 136
1 -4 -2 136 136 136
2 -4 -2 136 136 136
3 -4 -2 136 136 136
4 -4 -2 136 136 136
5 -4 -2 136 136 136
0 -3 -2 136 136 136
1 -3 -2 136 136 136
2 -3 -2 136 136 136
3 -3 -2 119 119 119
-3 -2 -2 136 136 136
-2 -2 -2 136 136 136
-1 -2 -2 136 136 136
0 -2 -2 136 136 136
1 -2 -2 136 136 136
2 -2 -2 136 136 136
3 -2 -2 136 136 136
4 -2 -2 136 136 136
-3 -1 -2 136 136 136
-2 -1 -2 136 136 136
-1 -1 -2 136 136 136
0 -1 -2 136 136 136
1 -1 -2 136 136 136
2 -1 -2 136 136 136
3 -1 -2 136 136 136
-3 0 -2 136 136 136
-2 0 -2 136 136 136
-1 0 -2 136 136 136
0 0 -2 136 136 136
1 0 -2 136 136 136
2 0 -2 136 136 136
3 0 -2 136 136 136
-3 1 -2 136 136 136
-2 1 -2 136 136 136
-1 1 -2 136 136 136
0 1 -2 136 136 136
1 1 -2 136 136 136
2 1 -2 136 136 136
-2 2 -2 136 136 136
-1 2 -2 136 136 136
0 2 -2 136 136 136
1 2 -2 136 136 136
-1 3 -2 136 136 136
2 -6 -1 119 119 119
3 -6 -1 136 136 136
0 -5 -1 119 119 119
1 -5 -1 119 119 119
2 -5 -1 136 136 136
3 -5 -1 136 136 136
4 -5 -1 136 136 136
5 -5 -1 136 136 136
-3 -4 -1 136 136 136
-2 -4 -1 136 136 136
-1 -4 -1 119 119 119
0 -4 -1 136 136 136
1 -4 -1 136 136 136
2 -4 -1 136 136 136
3 -4 -1 136 136 136
4 -4 -1 136 136 136
5 -4 -1 136 136 136
-3 -3 -1 119 119 119
-2 -3 -1 136 136 136
-1 -3 -1 136 136 136
0 -3 -1 136 136 136
1 -3 -1 136 136 136
2 -3 -1 136 136 136
3 -3 -1 136 136 136
4 -3 -1 136 136 136
5 -3 -1 119 119 119
-4 -2 -1 119 119 119
-3 -2 -1 136 136 136
-2 -2 -1 136 136 136
-1 -2 -1 136 136 136
0 -2 -1 136 136 136
1 -2 -1 136 136 136
2 -2 -1 136 136 136
3 -2 -1 136 136 136
4 -2 -1 119 119 119
-4 -1 -1 119 119 119
-3 -1 -1 136 136 136
-2 -1 -1 136 136 136
-1 -1 -1 136 136 136
0 -1 -1 136 136 136
1 -1 -1 136 136 136
2 -1 -1 136 136 136
3 -1 -1 136 136 136
-4 0 -1 136 136 136
-3 0 -1 136 136 136
-2 0 -1 136 136 136
-1 0 -1 136 136 136
0 0 -1 136 136 136
1 0 -1 136 136 136
2 0 -1 136 136 136
3 0 -1 136 136 136
-4 1 -1 136 136 136
-3 1 -1 136 136 136
-2 1 -1 136 136 136
-1 1 -1 136 136 136
0 1 -1 136 136 136
1 1 -1 136 136 136
2 1 -1 136 136 136
-4 2 -1 136 136 136
-3 2 -1 136 136 136
-2 2 -1 136 136 136
-1 2 -1 136 136 136
0 2 -1 136 136 136
1 2 -1 136 136 136
-4 3 -1 136 136 136
-3 3 -1 136 136 136
-2 3 -1 136 136 136
-1 3 -1 136 136 136
0 3 -1 136 136 136
-3 4 -1 136 136 136
-2 -5 0 119 119 119
-1 -5 0 119 119 119
0 -5 0 136 136 136
1 -5 0 136 136 136
2 -5 0 136 136 136
3 -5 0 136 136 136
4 -5 0 136 136 136
-3 -4 0 119 119 119
-2 -4 0 136 136 136
-1 -4 0 136 136 136
0 -4 0 136 136 136
1 -4 0 136 136 136
2 -4 0 136 136 136
3 -4 0 136 136 136
4 -4 0 136 136 136
5 -4 0 136 136 136
-4 -3 0 119 119 119
-3 -3 0 136 136 136
-2 -3 0 136 136 136
-1 -3 0 136 136 136
0 -3 0 136 136 136
1 -3 0 136 136 136
2 -3 0 136 136 136
3 -3 0 136 136 136
4 -3 0 119 119 119
-5 -2 0 136 136 136
-4 -2 0 136 136 136
-3 -2 0 136 136 136
-2 -2 0 136 136 136
-1 -2 0 136 136 136
0 -2 0 136 136 136
1 -2 0 136 136 136
2 -2 0 136 136 136
3 -2 0 136 136 136
4 -2 0 119 119 119
-5 -1 0 136 136 136
-4 -1 0 136 136 136
-3 -1 0 136 136 136
-2 -1 0 136 136 136
-1 -1 0 136 136 136
0 -1 0 136 136 136
1 -1 0 136 136 136
2 -1 0 136 136 136
3 -1 0 136 136 136
4 -1 0 119 119 119
-5 0 0 136 136 136
-4 0 0 136 136 136
-3 0 0 136 136 136
-2 0 0 136 136 136
-1 0 0 136 136 136
0 0 0 136 136 136
1 0 0 136 136 136
2 0 0 136 136 136
3 0 0 119 119 119
-5 1 0 136 136 136
-4 1 0 136 136 136
-3 1 0 136 136 136
-2 1 0 136 136 136
-1 1 0 136 136 136
0 1 0 136 136 136
1 1 0 136 136 136
2 1 0 119 119 119
-4 2 0 136 136 136
-3 2 0 136 136 136
-2 2 0 136 136 136
-1 2 0 136 136 136
0 2 0 136 136 136
1 2 0 119 119 119
-4 3 0 136 136 136
-3 3 0 119 119 119
-2 3 0 119 119 119
-1 3 0 136 136 136
0 3 0 136 136 136
-3 -5 1 136 136 136
-2 -5 1 136 136 136
-1 -5 1 136 136 136
0 -5 1 136 136 136
1 -5 1 136 136 136
-4 -4 1 119 119 119
-3 -4 1 136 136 136
-2 -4 1 136 136 136
-1 -4 1 136 136 136
0 -4 1 136 136 136
1 -4 1 136 136 136
2 -4 1 136 136 136
3 -4 1 136 136 136
-5 -3 1 119 119 119
-4 -3 1 170 170 170
-3 -3 1 136 136 136
-2 -3 1 136 136 136
-1 -3 1 136 136 136
0 -3 1 136 136 136
1 -3 1 136 136 136
2 -3 1 136 136 136
3 -3 1 136 136 136
4 -3 1 119 119 119
-5 -2 1 119 119 119
-4 -2 1 170 170 170
-3 -2 1 136 136 136
-2 -2 1 136 136 136
-1 -2 1 136 136 136
0 -2 1 136 136 136
1 -2 1 136 136 136
2 -2 1 136 136 136
3 -2 1 136 136 136
4 -2 1 136 136 136
-5 -1 1 119 119 119
-4 -1 1 170 170 170
-3 -1 1 136 136 136
-2 -1 1 136 136 136
-1 -1 1 136 136 136
0 -1 1 136 136 136
1 -1 1 136 136 136
2 -1 1 136 136 136
3 -1 1 136 136 136
4 -1 1 136 136 136
-4 0 1 170 170 170
-3 0 1 51 102 51
-2 0 1 136 136 136
-1 0 1 136 136 136
0 0 1 136 136 136
1 0 1 136 136 136
2 0 1 136 136 136
3 0 1 136 136 136
-3 1 1 51 102 51
-2 1 1 136 136 136
-1 1 1 136 136 136
0 1 1 136 136 136
1 1 1 136 136 136
2 1 1 119 119 119
-3 2 1 51 102 51
-2 2 1 51 102 51
-1 2 1 136 136 136
0 2 1 136 136 136
-2 3 1 170 170 170
-1 3 1 170 170 170
-1 -5 2 136 136 136
0 -5 2 136 136 136
1 -5 2 136 136 136
-1 -4 2 136 136 136
0 -4 2 136 136 136
1 -4 2 136 136 136
2 -4 2 51 102 51
3 -4 2 51 102 51
-1 -3 2 136 136 136
0 -3 2 136 136 136
1 -3 2 136 136 136
2 -3 2 136 136 136
3 -3 2 136 136 136
4 -3 2 51 102 51
-1 -2 2 136 136 136
0 -2 2 136 136 136
1 -2 2 136 136 136
2 -2 2 136 136 136
3 -2 2 119 119 119
4 -2 2 119 119 119
-1 -1 2 51 102 51
0 -1 2 136 136 136
1 -1 2 136 136 136
2 -1 2 136 136 136
3 -1 2 136 136 136
-2 0 2 136 136 136
-1 0 2 170 170 170
0 0 2 136 136 136
1 0 2 136 136 136
2 0 2 136 136 136
-1 1 2 136 136 136
0 1 2 136 136 136
-1 2 2 51 102 51
0 -4 3 136 136 136
0 -3 3 136 136 136
1 -3 3 136 136 136
2 -3 3 136 136 136
-1 -2 3 170 170 170
0 -2 3 170 170 170
1 -2 3 170 170 170
2 -2 3 119 119 119
0 -1 3 51 102 51
